Traceback (most recent call last):
  File "C:\Users\knajmajer\.conda\envs\jbook\Lib\site-packages\jupyter_cache\executors\utils.py", line 58, in single_nb_execution
    executenb(
  File "C:\Users\knajmajer\.conda\envs\jbook\Lib\site-packages\nbclient\client.py", line 1305, in execute
    return NotebookClient(nb=nb, resources=resources, km=km, **kwargs).execute()
           ^^^^^^^^^^^^^^^^^^^^^^^^^^^^^^^^^^^^^^^^^^^^^^^^^^^^^^^^^^^^^^^^^^^^^
  File "C:\Users\knajmajer\.conda\envs\jbook\Lib\site-packages\jupyter_core\utils\__init__.py", line 165, in wrapped
    return loop.run_until_complete(inner)
           ^^^^^^^^^^^^^^^^^^^^^^^^^^^^^^
  File "C:\Users\knajmajer\.conda\envs\jbook\Lib\asyncio\base_events.py", line 687, in run_until_complete
    return future.result()
           ^^^^^^^^^^^^^^^
  File "C:\Users\knajmajer\.conda\envs\jbook\Lib\site-packages\nbclient\client.py", line 705, in async_execute
    await self.async_execute_cell(
  File "C:\Users\knajmajer\.conda\envs\jbook\Lib\site-packages\nbclient\client.py", line 1058, in async_execute_cell
    await self._check_raise_for_error(cell, cell_index, exec_reply)
  File "C:\Users\knajmajer\.conda\envs\jbook\Lib\site-packages\nbclient\client.py", line 914, in _check_raise_for_error
    raise CellExecutionError.from_cell_and_msg(cell, exec_reply_content)
nbclient.exceptions.CellExecutionError: An error occurred while executing the following cell:
------------------
%run script.py
------------------


[1;31m---------------------------------------------------------------------------[0m
[1;31mOSError[0m                                   Traceback (most recent call last)
File [1;32m~\.conda\envs\jbook\Lib\site-packages\IPython\core\magics\execution.py:716[0m, in [0;36mExecutionMagics.run[1;34m(self, parameter_s, runner, file_finder)[0m
[0;32m    715[0m     fpath [38;5;241m=[39m arg_lst[[38;5;241m0[39m]
[1;32m--> 716[0m     filename [38;5;241m=[39m file_finder(fpath)
[0;32m    717[0m [38;5;28;01mexcept[39;00m [38;5;167;01mIndexError[39;00m [38;5;28;01mas[39;00m e:

File [1;32m~\.conda\envs\jbook\Lib\site-packages\IPython\utils\path.py:91[0m, in [0;36mget_py_filename[1;34m(name)[0m
[0;32m     90[0m         [38;5;28;01mreturn[39;00m py_name
[1;32m---> 91[0m [38;5;28;01mraise[39;00m [38;5;167;01mIOError[39;00m([38;5;124m"[39m[38;5;124mFile `[39m[38;5;132;01m%r[39;00m[38;5;124m` not found.[39m[38;5;124m"[39m [38;5;241m%[39m name)

[1;31mOSError[0m: File `'script.py'` not found.

The above exception was the direct cause of the following exception:

[1;31mException[0m                                 Traceback (most recent call last)
Cell [1;32mIn[12], line 1[0m
[1;32m----> 1[0m get_ipython()[38;5;241m.[39mrun_line_magic([38;5;124m'[39m[38;5;124mrun[39m[38;5;124m'[39m, [38;5;124m'[39m[38;5;124mscript.py[39m[38;5;124m'[39m)

File [1;32m~\.conda\envs\jbook\Lib\site-packages\IPython\core\interactiveshell.py:2480[0m, in [0;36mInteractiveShell.run_line_magic[1;34m(self, magic_name, line, _stack_depth)[0m
[0;32m   2478[0m     kwargs[[38;5;124m'[39m[38;5;124mlocal_ns[39m[38;5;124m'[39m] [38;5;241m=[39m [38;5;28mself[39m[38;5;241m.[39mget_local_scope(stack_depth)
[0;32m   2479[0m [38;5;28;01mwith[39;00m [38;5;28mself[39m[38;5;241m.[39mbuiltin_trap:
[1;32m-> 2480[0m     result [38;5;241m=[39m fn([38;5;241m*[39margs, [38;5;241m*[39m[38;5;241m*[39mkwargs)
[0;32m   2482[0m [38;5;66;03m# The code below prevents the output from being displayed[39;00m
[0;32m   2483[0m [38;5;66;03m# when using magics with decorator @output_can_be_silenced[39;00m
[0;32m   2484[0m [38;5;66;03m# when the last Python token in the expression is a ';'.[39;00m
[0;32m   2485[0m [38;5;28;01mif[39;00m [38;5;28mgetattr[39m(fn, magic[38;5;241m.[39mMAGIC_OUTPUT_CAN_BE_SILENCED, [38;5;28;01mFalse[39;00m):

File [1;32m~\.conda\envs\jbook\Lib\site-packages\IPython\core\magics\execution.py:727[0m, in [0;36mExecutionMagics.run[1;34m(self, parameter_s, runner, file_finder)[0m
[0;32m    725[0m     [38;5;28;01mif[39;00m os[38;5;241m.[39mname [38;5;241m==[39m [38;5;124m'[39m[38;5;124mnt[39m[38;5;124m'[39m [38;5;129;01mand[39;00m re[38;5;241m.[39mmatch([38;5;124mr[39m[38;5;124m"[39m[38;5;124m^[39m[38;5;124m'[39m[38;5;124m.*[39m[38;5;124m'[39m[38;5;124m$[39m[38;5;124m"[39m,fpath):
[0;32m    726[0m         warn([38;5;124m'[39m[38;5;124mFor Windows, use double quotes to wrap a filename: [39m[38;5;132;01m%r[39;00m[38;5;124mun [39m[38;5;124m"[39m[38;5;124mmypath[39m[38;5;130;01m\\[39;00m[38;5;124mmyfile.py[39m[38;5;124m"[39m[38;5;124m'[39m)
[1;32m--> 727[0m     [38;5;28;01mraise[39;00m [38;5;167;01mException[39;00m(msg) [38;5;28;01mfrom[39;00m [38;5;21;01me[39;00m
[0;32m    728[0m [38;5;28;01mexcept[39;00m [38;5;167;01mTypeError[39;00m:
[0;32m    729[0m     [38;5;28;01mif[39;00m fpath [38;5;129;01min[39;00m sys[38;5;241m.[39mmeta_path:

[1;31mException[0m: File `'script.py'` not found.

