Traceback (most recent call last):
  File "C:\Users\knajmajer\.conda\envs\jbook\Lib\site-packages\jupyter_cache\executors\utils.py", line 58, in single_nb_execution
    executenb(
  File "C:\Users\knajmajer\.conda\envs\jbook\Lib\site-packages\nbclient\client.py", line 1305, in execute
    return NotebookClient(nb=nb, resources=resources, km=km, **kwargs).execute()
           ^^^^^^^^^^^^^^^^^^^^^^^^^^^^^^^^^^^^^^^^^^^^^^^^^^^^^^^^^^^^^^^^^^^^^
  File "C:\Users\knajmajer\.conda\envs\jbook\Lib\site-packages\jupyter_core\utils\__init__.py", line 165, in wrapped
    return loop.run_until_complete(inner)
           ^^^^^^^^^^^^^^^^^^^^^^^^^^^^^^
  File "C:\Users\knajmajer\.conda\envs\jbook\Lib\asyncio\base_events.py", line 687, in run_until_complete
    return future.result()
           ^^^^^^^^^^^^^^^
  File "C:\Users\knajmajer\.conda\envs\jbook\Lib\site-packages\nbclient\client.py", line 705, in async_execute
    await self.async_execute_cell(
  File "C:\Users\knajmajer\.conda\envs\jbook\Lib\site-packages\nbclient\client.py", line 1058, in async_execute_cell
    await self._check_raise_for_error(cell, cell_index, exec_reply)
  File "C:\Users\knajmajer\.conda\envs\jbook\Lib\site-packages\nbclient\client.py", line 914, in _check_raise_for_error
    raise CellExecutionError.from_cell_and_msg(cell, exec_reply_content)
nbclient.exceptions.CellExecutionError: An error occurred while executing the following cell:
------------------
tuple_ex = (1, 2)
tuple_ex[0] = 3
------------------


[1;31m---------------------------------------------------------------------------[0m
[1;31mTypeError[0m                                 Traceback (most recent call last)
Cell [1;32mIn[25], line 2[0m
[0;32m      1[0m tuple_ex [38;5;241m=[39m ([38;5;241m1[39m, [38;5;241m2[39m)
[1;32m----> 2[0m tuple_ex[[38;5;241m0[39m] [38;5;241m=[39m [38;5;241m3[39m

[1;31mTypeError[0m: 'tuple' object does not support item assignment

