Traceback (most recent call last):
  File "C:\Users\knajmajer\.conda\envs\jbook\Lib\site-packages\jupyter_cache\executors\utils.py", line 58, in single_nb_execution
    executenb(
  File "C:\Users\knajmajer\.conda\envs\jbook\Lib\site-packages\nbclient\client.py", line 1305, in execute
    return NotebookClient(nb=nb, resources=resources, km=km, **kwargs).execute()
           ^^^^^^^^^^^^^^^^^^^^^^^^^^^^^^^^^^^^^^^^^^^^^^^^^^^^^^^^^^^^^^^^^^^^^
  File "C:\Users\knajmajer\.conda\envs\jbook\Lib\site-packages\jupyter_core\utils\__init__.py", line 165, in wrapped
    return loop.run_until_complete(inner)
           ^^^^^^^^^^^^^^^^^^^^^^^^^^^^^^
  File "C:\Users\knajmajer\.conda\envs\jbook\Lib\asyncio\base_events.py", line 687, in run_until_complete
    return future.result()
           ^^^^^^^^^^^^^^^
  File "C:\Users\knajmajer\.conda\envs\jbook\Lib\site-packages\nbclient\client.py", line 705, in async_execute
    await self.async_execute_cell(
  File "C:\Users\knajmajer\.conda\envs\jbook\Lib\site-packages\nbclient\client.py", line 1058, in async_execute_cell
    await self._check_raise_for_error(cell, cell_index, exec_reply)
  File "C:\Users\knajmajer\.conda\envs\jbook\Lib\site-packages\nbclient\client.py", line 914, in _check_raise_for_error
    raise CellExecutionError.from_cell_and_msg(cell, exec_reply_content)
nbclient.exceptions.CellExecutionError: An error occurred while executing the following cell:
------------------
from lime.wrappers.scikit_image import SegmentationAlgorithm

from lime import lime_image

explainer = lime_image.LimeImageExplainer(random_state=0)


segmentation_fn = SegmentationAlgorithm('quickshift', kernel_size=2,
                                        max_dist=5, ratio=0.2,
                                        random_seed=0)

explanation = explainer.explain_instance(X_test[1].astype('double'), model.predict,
                                         top_labels=3, num_samples=100, segmentation_fn=segmentation_fn, progress_bar = False)
------------------


[1;31m---------------------------------------------------------------------------[0m
[1;31mTypeError[0m                                 Traceback (most recent call last)
Cell [1;32mIn[16], line 12[0m
[0;32m      5[0m explainer [38;5;241m=[39m lime_image[38;5;241m.[39mLimeImageExplainer(random_state[38;5;241m=[39m[38;5;241m0[39m)
[0;32m      8[0m segmentation_fn [38;5;241m=[39m SegmentationAlgorithm([38;5;124m'[39m[38;5;124mquickshift[39m[38;5;124m'[39m, kernel_size[38;5;241m=[39m[38;5;241m2[39m,
[0;32m      9[0m                                         max_dist[38;5;241m=[39m[38;5;241m5[39m, ratio[38;5;241m=[39m[38;5;241m0.2[39m,
[0;32m     10[0m                                         random_seed[38;5;241m=[39m[38;5;241m0[39m)
[1;32m---> 12[0m explanation [38;5;241m=[39m explainer[38;5;241m.[39mexplain_instance(X_test[[38;5;241m1[39m][38;5;241m.[39mastype([38;5;124m'[39m[38;5;124mdouble[39m[38;5;124m'[39m), model[38;5;241m.[39mpredict,
[0;32m     13[0m                                          top_labels[38;5;241m=[39m[38;5;241m3[39m, num_samples[38;5;241m=[39m[38;5;241m100[39m, segmentation_fn[38;5;241m=[39msegmentation_fn, progress_bar [38;5;241m=[39m [38;5;28;01mFalse[39;00m)

[1;31mTypeError[0m: LimeImageExplainer.explain_instance() got an unexpected keyword argument 'progress_bar'

